[2023-12-20T11:45:26.538+0000] {scheduler_job_runner.py:781} ERROR - Executor reports task instance <TaskInstance: our_first_dag.first_task scheduled__2023-12-18T00:00:00+00:00 [queued]> finished (failed) although the task says it's queued. (Info: None) Was the task killed externally?
