[2023-12-26T08:17:47.307+0000] {taskinstance.py:1957} INFO - Dependencies all met for dep_context=non-requeueable deps ti=<TaskInstance: dbt_dag.dbt_run scheduled__2021-08-03T00:00:00+00:00 [queued]>
[2023-12-26T08:17:47.344+0000] {taskinstance.py:1957} INFO - Dependencies all met for dep_context=requeueable deps ti=<TaskInstance: dbt_dag.dbt_run scheduled__2021-08-03T00:00:00+00:00 [queued]>
[2023-12-26T08:17:47.345+0000] {taskinstance.py:2171} INFO - Starting attempt 1 of 6
[2023-12-26T08:17:47.397+0000] {taskinstance.py:2192} INFO - Executing <Task(BashOperator): dbt_run> on 2021-08-03 00:00:00+00:00
[2023-12-26T08:17:47.407+0000] {standard_task_runner.py:60} INFO - Started process 3975 to run task
[2023-12-26T08:17:47.418+0000] {standard_task_runner.py:87} INFO - Running: ['***', 'tasks', 'run', 'dbt_dag', 'dbt_run', 'scheduled__2021-08-03T00:00:00+00:00', '--job-id', '5096', '--raw', '--subdir', 'DAGS_FOLDER/first_dat.py', '--cfg-path', '/tmp/tmp_r6y856o']
[2023-12-26T08:17:47.428+0000] {standard_task_runner.py:88} INFO - Job 5096: Subtask dbt_run
[2023-12-26T08:17:47.586+0000] {task_command.py:423} INFO - Running <TaskInstance: dbt_dag.dbt_run scheduled__2021-08-03T00:00:00+00:00 [running]> on host 29b3723064ac
[2023-12-26T08:17:47.900+0000] {taskinstance.py:2481} INFO - Exporting env vars: AIRFLOW_CTX_DAG_OWNER='abrham' AIRFLOW_CTX_DAG_ID='dbt_dag' AIRFLOW_CTX_TASK_ID='dbt_run' AIRFLOW_CTX_EXECUTION_DATE='2021-08-03T00:00:00+00:00' AIRFLOW_CTX_TRY_NUMBER='1' AIRFLOW_CTX_DAG_RUN_ID='scheduled__2021-08-03T00:00:00+00:00'
[2023-12-26T08:17:47.902+0000] {subprocess.py:63} INFO - Tmp dir root location: /tmp
[2023-12-26T08:17:47.903+0000] {subprocess.py:75} INFO - Running command: ['/usr/bin/bash', '-c', 'dbt run --profiles-dir ../dbt_warehouse']
[2023-12-26T08:17:47.951+0000] {subprocess.py:86} INFO - Output:
[2023-12-26T08:17:47.960+0000] {subprocess.py:93} INFO - /usr/bin/bash: line 1: dbt: command not found
[2023-12-26T08:17:47.961+0000] {subprocess.py:97} INFO - Command exited with return code 127
[2023-12-26T08:17:47.993+0000] {taskinstance.py:2699} ERROR - Task failed with exception
Traceback (most recent call last):
  File "/home/airflow/.local/lib/python3.8/site-packages/airflow/models/taskinstance.py", line 433, in _execute_task
    result = execute_callable(context=context, **execute_callable_kwargs)
  File "/home/airflow/.local/lib/python3.8/site-packages/airflow/operators/bash.py", line 212, in execute
    raise AirflowException(
airflow.exceptions.AirflowException: Bash command failed. The command returned a non-zero exit code 127.
[2023-12-26T08:17:48.014+0000] {taskinstance.py:1138} INFO - Marking task as UP_FOR_RETRY. dag_id=dbt_dag, task_id=dbt_run, execution_date=20210803T000000, start_date=20231226T081747, end_date=20231226T081748
[2023-12-26T08:17:48.260+0000] {standard_task_runner.py:107} ERROR - Failed to execute job 5096 for task dbt_run (Bash command failed. The command returned a non-zero exit code 127.; 3975)
[2023-12-26T08:17:48.334+0000] {local_task_job_runner.py:234} INFO - Task exited with return code 1
[2023-12-26T08:17:48.427+0000] {taskinstance.py:3281} INFO - 0 downstream tasks scheduled from follow-on schedule check
