[2023-12-26T08:17:45.991+0000] {taskinstance.py:1957} INFO - Dependencies all met for dep_context=non-requeueable deps ti=<TaskInstance: dbt_dag.dbt_run scheduled__2021-07-30T00:00:00+00:00 [queued]>
[2023-12-26T08:17:46.007+0000] {taskinstance.py:1957} INFO - Dependencies all met for dep_context=requeueable deps ti=<TaskInstance: dbt_dag.dbt_run scheduled__2021-07-30T00:00:00+00:00 [queued]>
[2023-12-26T08:17:46.008+0000] {taskinstance.py:2171} INFO - Starting attempt 1 of 6
[2023-12-26T08:17:46.139+0000] {taskinstance.py:2192} INFO - Executing <Task(BashOperator): dbt_run> on 2021-07-30 00:00:00+00:00
[2023-12-26T08:17:46.146+0000] {standard_task_runner.py:60} INFO - Started process 3964 to run task
[2023-12-26T08:17:46.163+0000] {standard_task_runner.py:87} INFO - Running: ['***', 'tasks', 'run', 'dbt_dag', 'dbt_run', 'scheduled__2021-07-30T00:00:00+00:00', '--job-id', '5092', '--raw', '--subdir', 'DAGS_FOLDER/first_dat.py', '--cfg-path', '/tmp/tmpl0m3ea5a']
[2023-12-26T08:17:46.175+0000] {standard_task_runner.py:88} INFO - Job 5092: Subtask dbt_run
[2023-12-26T08:17:46.344+0000] {task_command.py:423} INFO - Running <TaskInstance: dbt_dag.dbt_run scheduled__2021-07-30T00:00:00+00:00 [running]> on host 29b3723064ac
[2023-12-26T08:17:46.699+0000] {taskinstance.py:2481} INFO - Exporting env vars: AIRFLOW_CTX_DAG_OWNER='abrham' AIRFLOW_CTX_DAG_ID='dbt_dag' AIRFLOW_CTX_TASK_ID='dbt_run' AIRFLOW_CTX_EXECUTION_DATE='2021-07-30T00:00:00+00:00' AIRFLOW_CTX_TRY_NUMBER='1' AIRFLOW_CTX_DAG_RUN_ID='scheduled__2021-07-30T00:00:00+00:00'
[2023-12-26T08:17:46.701+0000] {subprocess.py:63} INFO - Tmp dir root location: /tmp
[2023-12-26T08:17:46.708+0000] {subprocess.py:75} INFO - Running command: ['/usr/bin/bash', '-c', 'dbt run --profiles-dir ../dbt_warehouse']
[2023-12-26T08:17:46.752+0000] {subprocess.py:86} INFO - Output:
[2023-12-26T08:17:46.757+0000] {subprocess.py:93} INFO - /usr/bin/bash: line 1: dbt: command not found
[2023-12-26T08:17:46.759+0000] {subprocess.py:97} INFO - Command exited with return code 127
[2023-12-26T08:17:46.789+0000] {taskinstance.py:2699} ERROR - Task failed with exception
Traceback (most recent call last):
  File "/home/airflow/.local/lib/python3.8/site-packages/airflow/models/taskinstance.py", line 433, in _execute_task
    result = execute_callable(context=context, **execute_callable_kwargs)
  File "/home/airflow/.local/lib/python3.8/site-packages/airflow/operators/bash.py", line 212, in execute
    raise AirflowException(
airflow.exceptions.AirflowException: Bash command failed. The command returned a non-zero exit code 127.
[2023-12-26T08:17:46.813+0000] {taskinstance.py:1138} INFO - Marking task as UP_FOR_RETRY. dag_id=dbt_dag, task_id=dbt_run, execution_date=20210730T000000, start_date=20231226T081745, end_date=20231226T081746
[2023-12-26T08:17:46.872+0000] {standard_task_runner.py:107} ERROR - Failed to execute job 5092 for task dbt_run (Bash command failed. The command returned a non-zero exit code 127.; 3964)
[2023-12-26T08:17:46.921+0000] {local_task_job_runner.py:234} INFO - Task exited with return code 1
[2023-12-26T08:17:47.071+0000] {taskinstance.py:3281} INFO - 0 downstream tasks scheduled from follow-on schedule check
