[2023-12-20T11:42:09.084+0000] {taskinstance.py:1957} INFO - Dependencies all met for dep_context=non-requeueable deps ti=<TaskInstance: our_first_dag.second_id scheduled__2023-10-02T00:00:00+00:00 [queued]>
[2023-12-20T11:42:09.099+0000] {taskinstance.py:1957} INFO - Dependencies all met for dep_context=requeueable deps ti=<TaskInstance: our_first_dag.second_id scheduled__2023-10-02T00:00:00+00:00 [queued]>
[2023-12-20T11:42:09.100+0000] {taskinstance.py:2171} INFO - Starting attempt 1 of 6
[2023-12-20T11:42:09.136+0000] {taskinstance.py:2192} INFO - Executing <Task(BashOperator): second_id> on 2023-10-02 00:00:00+00:00
[2023-12-20T11:42:09.144+0000] {standard_task_runner.py:60} INFO - Started process 3881 to run task
[2023-12-20T11:42:09.150+0000] {standard_task_runner.py:87} INFO - Running: ['***', 'tasks', 'run', 'our_first_dag', 'second_id', 'scheduled__2023-10-02T00:00:00+00:00', '--job-id', '814', '--raw', '--subdir', 'DAGS_FOLDER/first_dat.py', '--cfg-path', '/tmp/tmpuj3o7izt']
[2023-12-20T11:42:09.153+0000] {standard_task_runner.py:88} INFO - Job 814: Subtask second_id
[2023-12-20T11:42:09.226+0000] {task_command.py:423} INFO - Running <TaskInstance: our_first_dag.second_id scheduled__2023-10-02T00:00:00+00:00 [running]> on host 29b3723064ac
[2023-12-20T11:42:09.343+0000] {taskinstance.py:2481} INFO - Exporting env vars: AIRFLOW_CTX_DAG_OWNER='abrham' AIRFLOW_CTX_DAG_ID='our_first_dag' AIRFLOW_CTX_TASK_ID='second_id' AIRFLOW_CTX_EXECUTION_DATE='2023-10-02T00:00:00+00:00' AIRFLOW_CTX_TRY_NUMBER='1' AIRFLOW_CTX_DAG_RUN_ID='scheduled__2023-10-02T00:00:00+00:00'
[2023-12-20T11:42:09.344+0000] {subprocess.py:63} INFO - Tmp dir root location: /tmp
[2023-12-20T11:42:09.345+0000] {subprocess.py:75} INFO - Running command: ['/usr/bin/bash', '-c', []]
[2023-12-20T11:42:09.347+0000] {taskinstance.py:2699} ERROR - Task failed with exception
Traceback (most recent call last):
  File "/home/airflow/.local/lib/python3.8/site-packages/airflow/models/taskinstance.py", line 433, in _execute_task
    result = execute_callable(context=context, **execute_callable_kwargs)
  File "/home/airflow/.local/lib/python3.8/site-packages/airflow/operators/bash.py", line 203, in execute
    result = self.subprocess_hook.run_command(
  File "/home/airflow/.local/lib/python3.8/site-packages/airflow/hooks/subprocess.py", line 77, in run_command
    self.sub_process = Popen(
  File "/usr/local/lib/python3.8/subprocess.py", line 858, in __init__
    self._execute_child(args, executable, preexec_fn, close_fds,
  File "/usr/local/lib/python3.8/subprocess.py", line 1655, in _execute_child
    self.pid = _posixsubprocess.fork_exec(
TypeError: expected str, bytes or os.PathLike object, not list
[2023-12-20T11:42:09.364+0000] {taskinstance.py:1138} INFO - Marking task as UP_FOR_RETRY. dag_id=our_first_dag, task_id=second_id, execution_date=20231002T000000, start_date=20231220T114209, end_date=20231220T114209
[2023-12-20T11:42:09.391+0000] {standard_task_runner.py:107} ERROR - Failed to execute job 814 for task second_id (expected str, bytes or os.PathLike object, not list; 3881)
[2023-12-20T11:42:09.402+0000] {local_task_job_runner.py:234} INFO - Task exited with return code 1
[2023-12-20T11:42:09.427+0000] {taskinstance.py:3281} INFO - 0 downstream tasks scheduled from follow-on schedule check
